<sdf version='1.6'>
  <model name='Scorpio'>
    <link name='tower'>
      <pose frame=''>0 0 0.5 0 0 -1.57</pose>
      <inertial>
        <pose frame=''>0.105684 0.103692 0.827326 0 -0 0</pose>
        <mass>1.4355</mass>
        <inertia>
          <ixx>0.122996</ixx>
          <ixy>-0.00226092</ixy>
          <ixz>-0.00536086</ixz>
          <iyy>0.123731</iyy>
          <iyz>-0.00517601</iyz>
          <izz>0.104924</izz>
        </inertia>
      </inertial>
      <visual name='tower_visual'>
        <pose frame=''>0 0 0.7749 0 -0 0</pose>
        <geometry>
          <box>
            <size>0.2 0.2 0.025</size>
          </box>
        </geometry>
      </visual>
      <visual name='tower_visual_1'>
        <pose frame=''>0 0 0.1 0 -0 0</pose>
        <geometry>
          <box>
            <size>0.0762 0.0762 1.3624</size>
          </box>
        </geometry>
      </visual>
      <visual name='tower_fixed_joint_lump__scorpio_ground_visual_2'>
        <pose frame=''>0.1375 0.1275 0.8744 0 -0 0</pose>
        <geometry>
          <mesh>
            <scale>1 1 1</scale>
            <uri>model://gazebo_scorpio_plugin/robots/meshes/scorpio_ground_hull.dae</uri>
          </mesh>
        </geometry>
      </visual>
    </link>
    <joint name='tower_mount' type='fixed'>
      <child>tower</child>
      <parent>world</parent>
    </joint>
    <link name='link1'>
      <pose frame=''>0.127609 -0.137398 1.35628 0 0 -1.57</pose>
      <inertial>
        <pose frame=''>0.048165 0.066069 -0.007523 0 -0 0</pose>
        <mass>0.971059</mass>
        <inertia>
          <ixx>0.00212363</ixx>
          <ixy>2.469e-05</ixy>
          <ixz>-0.00023024</ixz>
          <iyy>0.00183055</iyy>
          <iyz>-4.18e-06</iyz>
          <izz>0.001621</izz>
        </inertia>
      </inertial>
      <visual name='link1_visual'>
        <pose frame=''>0 0 0 0 -0 0</pose>
        <geometry>
          <mesh>
            <scale>1 1 1</scale>
            <uri>model://gazebo_scorpio_plugin/robots/meshes/scorpio_yaw1_hull.dae</uri>
          </mesh>
        </geometry>
      </visual>
    </link>
    <joint name='joint1' type='revolute'>
      <child>link1</child>
      <parent>tower</parent>
      <axis>
        <xyz>0 0 1</xyz>
        <limit>
          <lower>-1e+16</lower>
          <upper>1e+16</upper>
        </limit>
        <dynamics>
          <spring_reference>0</spring_reference>
          <spring_stiffness>0</spring_stiffness>
        </dynamics>
        <use_parent_model_frame>1</use_parent_model_frame>
      </axis>
    </joint>
    <link name='link2'>
      <pose frame=''>0.192681 -0.227347 1.3963 -1.5708 -0 -1.57</pose>
      <inertial>
        <pose frame=''>0.12123 -0.00077 0.007304 0 -0 0</pose>
        <mass>0.861013</mass>
        <inertia>
          <ixx>0.00102826</ixx>
          <ixy>2.087e-05</ixy>
          <ixz>-0.00011564</ixz>
          <iyy>0.00504132</iyy>
          <iyz>-6.39e-06</iyz>
          <izz>0.0057625</izz>
        </inertia>
      </inertial>
      <visual name='link2_visual'>
        <pose frame=''>0 0 0 1.5708 -0 0</pose>
        <geometry>
          <mesh>
            <scale>1 1 1</scale>
            <uri>model://gazebo_scorpio_plugin/robots/meshes/parallel__scorpio_elev1__l3_hull.dae</uri>
          </mesh>
        </geometry>
      </visual>
    </link>
    <joint name='joint2' type='revolute'>
      <child>link2</child>
      <parent>link1</parent>
      <axis>
        <xyz>1 0.000796 -4e-06</xyz>
        <limit>
          <lower>-1e+16</lower>
          <upper>1e+16</upper>
        </limit>
        <dynamics>
          <spring_reference>0</spring_reference>
          <spring_stiffness>0</spring_stiffness>
        </dynamics>
        <use_parent_model_frame>1</use_parent_model_frame>
      </axis>
    </joint>
    <link name='link3'>
      <pose frame=''>0.192856 -0.447347 1.3963 -1.5708 -0 -1.57</pose>
      <inertial>
        <pose frame=''>0.055399 -0.045509 0.033051 0 -0 0</pose>
        <mass>0.96507</mass>
        <inertia>
          <ixx>0.00194689</ixx>
          <ixy>-0.00041897</ixy>
          <ixz>-1.187e-05</ixz>
          <iyy>0.0010858</iyy>
          <iyz>-2.04e-06</iyz>
          <izz>0.00181433</izz>
        </inertia>
      </inertial>
      <visual name='link3_visual'>
        <pose frame=''>0 0.075025 0 1.5708 -0 0</pose>
        <geometry>
          <mesh>
            <scale>1 1 1</scale>
            <uri>model://gazebo_scorpio_plugin/robots/meshes/parallel__scorpio_elev1__l2_hull.dae</uri>
          </mesh>
        </geometry>
      </visual>
    </link>
    <joint name='joint3' type='revolute'>
      <child>link3</child>
      <parent>link2</parent>
      <axis>
        <xyz>1 0.000796 -4e-06</xyz>
        <limit>
          <lower>-1e+16</lower>
          <upper>1e+16</upper>
        </limit>
        <dynamics>
          <spring_reference>0</spring_reference>
          <spring_stiffness>0</spring_stiffness>
        </dynamics>
        <use_parent_model_frame>1</use_parent_model_frame>
      </axis>
    </joint>
    <link name='link4'>
      <pose frame=''>0.192856 -0.447347 1.32128 -1.5708 -0 -1.57</pose>
      <inertial>
        <pose frame=''>0.119681 0.000157 0.000771 0 -0 0</pose>
        <mass>1.09011</mass>
        <inertia>
          <ixx>0.00164433</ixx>
              <!--<dynamics>-->
                  <!--<spring_reference>0</spring_reference>-->
          <ixy>1.99947e-06</ixy>
          <ixz>-0.000122783</ixz>
          <iyy>0.00611581</iyy>
          <iyz>8.77e-06</iyz>
          <izz>0.00722538</izz>
        </inertia>
      </inertial>
      <visual name='link4_visual'>
        <pose frame=''>-0.22 0 0 1.5708 -0 0</pose>
        <geometry>
          <mesh>
            <scale>1 1 1</scale>
            <uri>model://gazebo_scorpio_plugin/robots/meshes/parallel__scorpio_elev1__l1_hull.dae</uri>
          </mesh>
        </geometry>
      </visual>
    </link>
    <joint name='joint4' type='revolute'>
      <child>link4</child>
      <parent>link3</parent>
      <axis>
        <xyz>1 0.000796 -4e-06</xyz>
       <limit>
          <lower>-1e+16</lower>
          <upper>1e+16</upper>
        </limit>
        <dynamics>
          <spring_reference>0</spring_reference>
          <spring_stiffness>0</spring_stiffness>
        </dynamics>
        <use_parent_model_frame>1</use_parent_model_frame>
      </axis>
    </joint>

    <joint type="revolute" name="parallel1">
        <pose> 0.089949 0.065072 -0.040025 -1.57 0 0 </pose>
        <parent>link4</parent>
        <child>link1</child>
        <axis>
            <xyz>0 0 1</xyz>
        </axis>
        <physics>
            <ode>
                <implicit_spring_damper>1</implicit_spring_damper>
                <cfm_damping>1</cfm_damping>
                <limit>
                    <cfm>0</cfm>
                    <erp>0.2</erp>
                </limit>
            </ode>
        </physics>
    </joint>


    <link name='link5'>
      <pose frame=''>0.127908 -0.512398 1.36131 0 0 -1.57</pose>
      <inertial>
        <pose frame=''>0.048804 0.065745 -0.007658 0 -0 0</pose>
        <mass>0.932292</mass>
        <inertia>
          <ixx>0.00175861</ixx>
          <ixy>3.237e-05</ixy>
          <ixz>-0.00022338</ixz>
          <iyy>0.00151576</iyy>
          <iyz>-2.89e-06</iyz>
          <izz>0.00153999</izz>
        </inertia>
      </inertial>
      <visual name='link5_visual'>
        <pose frame=''>0 0 0 0 -0 0</pose>
        <geometry>
          <mesh>
            <scale>1 1 1</scale>
            <uri>model://gazebo_scorpio_plugin/robots/meshes/scorpio_yaw2_hull.dae</uri>
          </mesh>
        </geometry>
      </visual>
    </link>
    <joint name='joint5' type='revolute'>
      <child>link5</child>
      <parent>link3</parent>
      <axis>
        <xyz>0 0 1</xyz>
        <limit>
          <lower>-1e+16</lower>
          <upper>1e+16</upper>
        </limit>
        <dynamics>
          <spring_reference>0</spring_reference>
          <spring_stiffness>0</spring_stiffness>
        </dynamics>
        <use_parent_model_frame>1</use_parent_model_frame>
      </axis>
    </joint>
    <link name='link6'>
      <pose frame=''>0.19298 -0.602347 1.40133 -1.5708 -0 -1.57</pose>
      <inertial>
        <pose frame=''>0.12123 -0.00077 0.007304 0 -0 0</pose>
        <mass>0.861013</mass>
        <inertia>
          <ixx>0.00102826</ixx>
          <ixy>2.087e-05</ixy>
          <ixz>-0.00011564</ixz>
          <iyy>0.00504132</iyy>
          <iyz>-6.39e-06</iyz>
          <izz>0.0057625</izz>
        </inertia>
      </inertial>
      <visual name='link6_visual'>
        <pose frame=''>0 0 0 1.5708 -0 0</pose>
        <geometry>
          <mesh>
            <scale>1 1 1</scale>
            <uri>model://gazebo_scorpio_plugin/robots/meshes/parallel__scorpio_elev2__l3_hull.dae</uri>
          </mesh>
        </geometry>
      </visual>
    </link>
    <joint name='joint6' type='revolute'>
      <child>link6</child>
      <parent>link5</parent>
      <axis>
        <xyz>1 0.000796 -4e-06</xyz>
        <limit>
          <lower>-1e+16</lower>
          <upper>1e+16</upper>
        </limit>
        <dynamics>
          <spring_reference>0</spring_reference>
          <spring_stiffness>0</spring_stiffness>
        </dynamics>
        <use_parent_model_frame>1</use_parent_model_frame>
      </axis>
    </joint>
    <link name='link7'>
      <pose frame=''>0.193155 -0.822346 1.40133 -1.5708 -0 -1.57</pose>
      <inertial>
        <pose frame=''>0.068511 0.001349 0.028888 0 -0 0</pose>
        <mass>0.793597</mass>
        <inertia>
          <ixx>0.000851673</ixx>
          <ixy>-4.48895e-05</ixy>
          <ixz>-3.20398e-05</ixz>
          <iyy>0.00101318</iyy>
          <iyz>2.71284e-07</iyz>
          <izz>0.00103857</izz>
        </inertia>
      </inertial>
      <visual name='link7_visual'>
        <pose frame=''>0 0.075025 0 1.5708 -0 0</pose>
        <geometry>
          <mesh>
            <scale>1 1 1</scale>
            <uri>model://gazebo_scorpio_plugin/robots/meshes/parallel__scorpio_elev2__l2_hull.dae</uri>
          </mesh>
        </geometry>
      </visual>
    </link>
    <joint name='joint7' type='revolute'>
      <child>link7</child>
      <parent>link6</parent>
      <axis>
        <xyz>1 0.000796 -4e-06</xyz>
        <limit>
          <lower>-1e+16</lower>
          <upper>1e+16</upper>
        </limit>
        <dynamics>
          <spring_reference>0</spring_reference>
          <spring_stiffness>0</spring_stiffness>
        </dynamics>
        <use_parent_model_frame>1</use_parent_model_frame>
      </axis>
    </joint>
    <link name='link8'>
      <pose frame=''>0.193155 -0.822346 1.32631 -1.5708 -0 -1.57</pose>
      <inertial>
        <pose frame=''>0.119681 0.000157 0.000771 0 -0 0</pose>
        <mass>1.09011</mass>
        <inertia>
          <ixx>0.00164433</ixx>
          <ixy>1.99947e-06</ixy>
          <ixz>-0.000122783</ixz>
          <iyy>0.00611581</iyy>
          <iyz>8.77e-06</iyz>
          <izz>0.00722538</izz>
        </inertia>
      </inertial>
      <visual name='link8_visual'>
        <pose frame=''>-0.22 0 0 1.5708 -0 0</pose>
        <geometry>
          <mesh>
            <scale>1 1 1</scale>
            <uri>model://gazebo_scorpio_plugin/robots/meshes/parallel__scorpio_elev2__l1_hull.dae</uri>
          </mesh>
        </geometry>
      </visual>
    </link>
    <joint name='joint8' type='revolute'>
      <child>link8</child>
      <parent>link7</parent>
      <axis>
        <xyz>1 0.000796 -4e-06</xyz>
        <limit>
          <lower>-1e+16</lower>
          <upper>1e+16</upper>
        </limit>
        <dynamics>
          <spring_reference>0</spring_reference>
          <spring_stiffness>0</spring_stiffness>
        </dynamics>
        <use_parent_model_frame>1</use_parent_model_frame>
      </axis>
    </joint>

    <joint type="revolute" name="parallel2">
        <pose> 0.089949 0.065072 -0.040025 -1.57 0 0 </pose>
        <parent>link8</parent>
        <child>link5</child>
        <axis>
            <xyz>0 0 1</xyz>
        </axis>
        <!--<physics>-->
            <!--<ode>-->
                <!--<implicit_spring_damper>1</implicit_spring_damper>-->
                <!--<cfm_damping>1</cfm_damping>-->
                <!--<limit>-->
                    <!--<cfm>0</cfm>-->
                    <!--<erp>0.2</erp>-->
                <!--</limit>-->
            <!--</ode>-->
        <!--</physics>-->
    </joint>
 
    <link name='link9'>
      <pose frame=''>0.193235 -0.923306 1.37483 -0 -0.7854 -1.57</pose>
      <inertial>
        <pose frame=''>0.026188 -0.060267 -0.050294 0 -0 0</pose>
        <mass>0.617427</mass>
        <inertia>
          <ixx>0.00049346</ixx>
          <ixy>-5.954e-05</ixy>
          <ixz>-0.00015627</ixz>
          <iyy>0.0006792</iyy>
          <iyz>9.425e-05</iyz>
          <izz>0.00043236</izz>
        </inertia>
      </inertial>
      <visual name='link9_visual'>
        <pose frame=''>0 0 0 0 -0 0</pose>
        <geometry>
          <mesh>
            <scale>1 1 1</scale>
            <uri>model://gazebo_scorpio_plugin/robots/meshes/scorpio_wrist_skewed_hull.dae</uri>
          </mesh>
        </geometry>
      </visual>
    </link>
    <joint name='joint9' type='revolute'>
      <child>link9</child>
      <parent>link7</parent>
      <axis>
        <xyz>-0.000563 0.707108 0.707105</xyz>
        <limit>
          <lower>-1e+16</lower>
          <upper>1e+16</upper>
        </limit>
        <dynamics>
          <spring_reference>0</spring_reference>
          <spring_stiffness>0</spring_stiffness>
        </dynamics>
        <use_parent_model_frame>1</use_parent_model_frame>
      </axis>
    </joint>
    <link name='scorpio_wrist_pitch'>
      <pose frame=''>0.149568 -0.99031 1.3568 -0 -0 -1.57</pose>
      <inertial>
        <pose frame=''>-0.000225 0.050304 0.002343 0 -0 0</pose>
        <mass>0.565016</mass>
        <inertia>
          <ixx>0.00042006</ixx>
          <ixy>-5.58e-06</ixy>
          <ixz>9.3e-07</ixz>
          <iyy>0.00021226</iyy>
          <iyz>-1.417e-05</iyz>
          <izz>0.00052578</izz>
        </inertia>
      </inertial>
      <visual name='scorpio_wrist_pitch_visual'>
        <pose frame=''>0 0 0 0 -0 0</pose>
        <geometry>
          <mesh>
            <scale>1 1 1</scale>
            <uri>model://gazebo_scorpio_plugin/robots/meshes/scorpio_wrist_pitch_hull.dae</uri>
          </mesh>
        </geometry>
      </visual>
    </link>
    <joint name='joint10' type='revolute'>
      <child>scorpio_wrist_pitch</child>
      <parent>link9</parent>
      <axis>
        <xyz>1 0.000796 -0</xyz>
        <limit>
          <lower>-1e+16</lower>
          <upper>1e+16</upper>
        </limit>
        <dynamics>
          <spring_reference>0</spring_reference>
          <spring_stiffness>0</spring_stiffness>
        </dynamics>
        <use_parent_model_frame>1</use_parent_model_frame>
      </axis>
    </joint>
    <link name='gripper_attachment_point'>
      <pose frame=''>0.193288 -0.990275 1.33952 -0 0 0.0008</pose>
      <inertial>
        <pose frame=''>0.000171 -4e-06 -0.067513 0 -0 0</pose>
        <mass>0.466137</mass>
        <inertia>
          <ixx>0.00101166</ixx>
          <ixy>6.67846e-10</ixy>
          <ixz>9.65747e-07</ixz>
          <iyy>0.00134093</iyy>
          <iyz>-4.75073e-08</iyz>
          <izz>0.000826279</izz>
        </inertia>
      </inertial>
      <!--<collision name='gripper_attachment_point_fixed_joint_lump__robotiq_85_base_link_collision'>-->
        <!--<pose frame=''>0 0 -0.028 3.1415 -0 0</pose>-->
        <!--<geometry>-->
          <!--<mesh>-->
            <!--<scale>1 1 1</scale>-->
            <!--<uri>model://gazebo_scorpio_plugin/robots/meshes/robotiq_85_base_link_coarse.STL</uri>-->
          <!--</mesh>-->
        <!--</geometry>-->
      <!--</collision>-->
      <!--<collision name='gripper_attachment_point_fixed_joint_lump__left_outer_knuckle_collision_1'>-->
        <!--<pose frame=''>0.030601 -6e-06 -0.090792 3.1415 -0 0</pose>-->
        <!--<geometry>-->
          <!--<mesh>-->
            <!--<scale>1 1 1</scale>-->
            <!--<uri>model://gazebo_scorpio_plugin/robots/meshes/outer_knuckle_coarse.STL</uri>-->
          <!--</mesh>-->
        <!--</geometry>-->
      <!--</collision>-->
      <!--<collision name='gripper_attachment_point_fixed_joint_lump__left_outer_finger_collision_2'>-->
        <!--<pose frame=''>0.062292 -6e-06 -0.088858 3.1415 -0 0</pose>-->
        <!--<geometry>-->
          <!--<mesh>-->
            <!--<scale>1 1 1</scale>-->
            <!--<uri>model://gazebo_scorpio_plugin/robots/meshes/outer_finger_coarse.STL</uri>-->
          <!--</mesh>-->
        <!--</geometry>-->
      <!--</collision>-->
      <!--<collision name='gripper_attachment_point_fixed_joint_lump__left_inner_knuckle_collision_3'>-->
        <!--<pose frame=''>0.0127 -6e-06 -0.097308 3.1415 -0 0</pose>-->
        <!--<geometry>-->
          <!--<mesh>-->
            <!--<scale>1 1 1</scale>-->
            <!--<uri>model://gazebo_scorpio_plugin/robots/meshes/inner_knuckle_coarse.STL</uri>-->
          <!--</mesh>-->
        <!--</geometry>-->
      <!--</collision>-->
      <!--<collision name='gripper_attachment_point_fixed_joint_lump__left_inner_finger_collision_4'>-->
        <!--<pose frame=''>0.047285 -1.1e-05 -0.142805 3.1415 -0 0</pose>-->
        <!--<geometry>-->
          <!--<mesh>-->
            <!--<scale>1 1 1</scale>-->
            <!--<uri>model://gazebo_scorpio_plugin/robots/meshes/inner_finger_coarse.STL</uri>-->
          <!--</mesh>-->
        <!--</geometry>-->
      <!--</collision>-->
      <!--<collision name='gripper_attachment_point_fixed_joint_lump__right_inner_knuckle_collision_5'>-->
        <!--<pose frame=''>-0.0127 -6e-06 -0.097308 -3.1415 -0 -3.14159</pose>-->
        <!--<geometry>-->
          <!--<mesh>-->
            <!--<scale>1 1 1</scale>-->
            <!--<uri>model://gazebo_scorpio_plugin/robots/meshes/inner_knuckle_coarse.STL</uri>-->
          <!--</mesh>-->
        <!--</geometry>-->
      <!--</collision>-->
      <!--<collision name='gripper_attachment_point_fixed_joint_lump__right_inner_finger_collision_6'>-->
        <!--<pose frame=''>-0.046806 -1.1e-05 -0.143165 -3.1415 -0 -3.14159</pose>-->
        <!--<geometry>-->
          <!--<mesh>-->
            <!--<scale>1 1 1</scale>-->
            <!--<uri>model://gazebo_scorpio_plugin/robots/meshes/inner_finger_coarse.STL</uri>-->
          <!--</mesh>-->
        <!--</geometry>-->
      <!--</collision>-->
      <!--<collision name='gripper_attachment_point_fixed_joint_lump__right_outer_knuckle_collision_7'>-->
        <!--<pose frame=''>-0.030601 -6e-06 -0.090792 -3.1415 -0 -3.14159</pose>-->
        <!--<geometry>-->
          <!--<mesh>-->
            <!--<scale>1 1 1</scale>-->
            <!--<uri>model://gazebo_scorpio_plugin/robots/meshes/outer_knuckle_coarse.STL</uri>-->
          <!--</mesh>-->
        <!--</geometry>-->
      <!--</collision>-->
      <!--<collision name='gripper_attachment_point_fixed_joint_lump__right_outer_finger_collision_8'>-->
        <!--<pose frame=''>-0.062311 -6e-06 -0.089191 -3.1415 -0 -3.14159</pose>-->
        <!--<geometry>-->
          <!--<mesh>-->
            <!--<scale>1 1 1</scale>-->
            <!--<uri>model://gazebo_scorpio_plugin/robots/meshes/outer_finger_coarse.STL</uri>-->
          <!--</mesh>-->
        <!--</geometry>-->
      <!--</collision>-->
      <visual name='gripper_attachment_point_fixed_joint_lump__wrist_ft_visual'>
        <pose frame=''>0 0 -0.014 0 -0 0</pose>
        <geometry>
          <cylinder>
            <length>0.028</length>
            <radius>0.02</radius>
          </cylinder>
        </geometry>
      </visual>
      <visual name='gripper_attachment_point_fixed_joint_lump__robotiq_85_base_link_visual_1'>
        <pose frame=''>0 0 -0.028 3.1415 -0 0</pose>
        <geometry>
          <mesh>
            <scale>1 1 1</scale>
            <uri>model://gazebo_scorpio_plugin/robots/meshes/robotiq_85_base_link_fine.STL</uri>
          </mesh>
        </geometry>
      </visual>
      <visual name='gripper_attachment_point_fixed_joint_lump__left_outer_knuckle_visual_2'>
        <pose frame=''>0.030601 -6e-06 -0.090792 3.1415 -0 0</pose>
        <geometry>
          <mesh>
            <scale>1 1 1</scale>
            <uri>model://gazebo_scorpio_plugin/robots/meshes/outer_knuckle_fine.STL</uri>
          </mesh>
        </geometry>
      </visual>
      <visual name='gripper_attachment_point_fixed_joint_lump__left_outer_finger_visual_3'>
        <pose frame=''>0.062292 -6e-06 -0.088858 3.1415 -0 0</pose>
        <geometry>
          <mesh>
            <scale>1 1 1</scale>
            <uri>model://gazebo_scorpio_plugin/robots/meshes/outer_finger_fine.STL</uri>
          </mesh>
        </geometry>
      </visual>
      <visual name='gripper_attachment_point_fixed_joint_lump__left_inner_knuckle_visual_4'>
        <pose frame=''>0.0127 -6e-06 -0.097308 3.1415 -0 0</pose>
        <geometry>
          <mesh>
            <scale>1 1 1</scale>
            <uri>model://gazebo_scorpio_plugin/robots/meshes/inner_knuckle_fine.STL</uri>
          </mesh>
        </geometry>
      </visual>
      <visual name='gripper_attachment_point_fixed_joint_lump__left_inner_finger_visual_5'>
        <pose frame=''>0.047285 -1.1e-05 -0.142805 3.1415 -0 0</pose>
        <geometry>
          <mesh>
            <scale>1 1 1</scale>
            <uri>model://gazebo_scorpio_plugin/robots/meshes/inner_finger_fine.STL</uri>
          </mesh>
        </geometry>
      </visual>
      <visual name='gripper_attachment_point_fixed_joint_lump__right_inner_knuckle_visual_6'>
        <pose frame=''>-0.0127 -6e-06 -0.097308 -3.1415 -0 -3.14159</pose>
        <geometry>
          <mesh>
            <scale>1 1 1</scale>
            <uri>model://gazebo_scorpio_plugin/robots/meshes/inner_knuckle_fine.STL</uri>
          </mesh>
        </geometry>
      </visual>
      <visual name='gripper_attachment_point_fixed_joint_lump__right_inner_finger_visual_7'>
        <pose frame=''>-0.046806 -1.1e-05 -0.143165 -3.1415 -0 -3.14159</pose>
        <geometry>
          <mesh>
            <scale>1 1 1</scale>
            <uri>model://gazebo_scorpio_plugin/robots/meshes/inner_finger_fine.STL</uri>
          </mesh>
        </geometry>
      </visual>
      <visual name='gripper_attachment_point_fixed_joint_lump__right_outer_knuckle_visual_8'>
        <pose frame=''>-0.030601 -6e-06 -0.090792 -3.1415 -0 -3.14159</pose>
        <geometry>
          <mesh>
            <scale>1 1 1</scale>
            <uri>model://gazebo_scorpio_plugin/robots/meshes/outer_knuckle_fine.STL</uri>
          </mesh>
        </geometry>
      </visual>
      <visual name='gripper_attachment_point_fixed_joint_lump__right_outer_finger_visual_9'>
        <pose frame=''>-0.062311 -6e-06 -0.089191 -3.1415 -0 -3.14159</pose>
        <geometry>
          <mesh>
            <scale>1 1 1</scale>
            <uri>model://gazebo_scorpio_plugin/robots/meshes/outer_finger_fine.STL</uri>
          </mesh>
        </geometry>
      </visual>
    </link>
    <joint name='joint11' type='revolute'>
      <child>gripper_attachment_point</child>
      <parent>scorpio_wrist_pitch</parent>
      <axis>
        <xyz>0 0 1</xyz>
        <limit>
          <lower>-3.1416</lower>
          <upper>3.1416</upper>
          <effort>200</effort>
          <velocity>0</velocity>
        </limit>
        <dynamics>
          <spring_reference>0</spring_reference>
          <spring_stiffness>0</spring_stiffness>
        </dynamics>
        <use_parent_model_frame>1</use_parent_model_frame>
      </axis>
    </joint>
  </model>
</sdf>
