<robot name="Scorpio">
    <link name="world">
    <inertial>
      <origin xyz="0 0 0" rpy="0 0 0" />
      <mass value="0.1" />
      <inertia ixx="0.1" ixy="0.1" ixz="0.1" iyy="0.1" iyz="0.1" izz="0.1" />
    </inertial>
   </link>
   <joint name="tower_mount" type="fixed">
    <!--<origin rpy="0 0 -1.57" xyz="3.5 1.0 0.5"/>-->
    <origin rpy="0 0 -1.57" xyz="0 0 0.5"/>
    <parent link="world"/>
    <child link="tower"/>
   </joint>
  <link name="tower">
    <inertial>
      <origin rpy="0 0 0" xyz="0 0 0.3937"/>
      <mass value="0.1"/>
      <inertia ixx="0.1" ixy="0" ixz="0" iyy="0.1" iyz="0" izz="0.1"/>
    </inertial>
    <visual>
      <origin rpy="0 0 0" xyz="0 0 0.7749"/>
      <geometry>
        <box size="0.200 0.200 0.025"/>
      </geometry>
      <material name="">
        <color rgba="0.75294 0.75294 0.75294 1"/>
      </material>
    </visual>
    <visual>
      <origin rpy="0 0 0" xyz="0 0 0.1"/>
      <geometry>
        <box size="0.0762 0.0762 1.3624"/>
        <!--<box size="0.0762 0.0762 1.7624"/>-->
      </geometry>
      <material name="">
        <color rgba="0.75294 0.75294 0.75294 1"/>
      </material>
    </visual>
  </link>
  <joint name="scorpio_mount" type="fixed">
    <origin rpy="0 0 0" xyz="0.0625 0.0625 0.7874"/>
    <parent link="tower"/>
    <child link="scorpio_mount"/>
  </joint>
  <link name="scorpio_mount">
    <inertial>
      <origin rpy="0 0 0" xyz="0 0 0"/>
      <mass value="0.001"/>
      <inertia ixx="0.0001" ixy="0" ixz="0" iyy="0.0001" iyz="0" izz="0.0001"/>
    </inertial>
  </link>
  <joint name="scorpio_ground" type="fixed">
    <origin rpy="0 0 0" xyz="0.075 0.065 0.087"/>
    <parent link="scorpio_mount"/>
    <child link="scorpio_ground"/>
  </joint>

  <link name="scorpio_ground">
    <inertial>
      <origin rpy="0 0 0" xyz="-0.023864 -0.016007 -0.014551"/>
      <mass value="1.3345"/>
      <inertia ixx="0.0015215" ixy="-0.0010805" ixz="-0.00043127" iyy="0.0022115" iyz="-0.00033943" izz="0.0024629"/>
    </inertial>
    <visual>
      <origin rpy="0 0 0" xyz="0 0 0"/>
      <geometry>
          <mesh filename="../../../../gazebo_scorpio_plugin/models/robots/meshes/scorpio_ground_hull.dae"/>
      </geometry>
      <material name="">
        <color rgba="0.75294 0.75294 0.75294 1"/>
      </material>
    </visual>
  </link>

 <joint name="joint1" type="continuous">
  <!--<origin rpy="0 0 0" xyz="0 0 -0.01812"/>-->
  <origin rpy="0 0 0" xyz="0 0 -0.01812"/>
    <parent link="scorpio_ground"/>
    <child link="link1"/>
    <axis xyz="0 0 1"/>
  </joint>

  <link name="link1">
    <inertial>
      <mass value="0.97105910"/>
      <origin rpy="0 0 0" xyz="0.04816471 0.06606926 -0.00752297"/>
      <inertia ixx="0.00212363" ixy="0.00002469" ixz="-0.00023024" iyy="0.00183055" iyz="-0.00000418" izz="0.00162100"/>
    </inertial>
    <visual>
      <origin rpy="0 0 0" xyz="0 0 0"/>
      <geometry>
        <mesh filename="../../../../gazebo_scorpio_plugin/models/robots/meshes/scorpio_yaw1_hull.dae"/>
      </geometry>
      <material name="">
        <color rgba="0.752941176470588 0.752941176470588 0.752941176470588 1"/>
      </material>
    </visual>
  </link>
  
   <joint name="joint2" type="continuous">
    <origin xyz="0.09 0.065 0.040025" rpy="-1.5708 0 0" />
    <parent link="link1" />
    <child link="link2" />
    <axis xyz="0 0 1" />
  </joint>

  <link name="link2">
  <inertial>
      <mass value="0.86101268"/>
      <origin rpy="0 0 0" xyz="0.12122970 -0.00077030 0.00730440"/>
      <inertia ixx="0.00102826" ixy="0.00002087" ixz="-0.00011564" iyy="0.00504132" iyz="-0.00000639" izz="0.00576250"/>
    </inertial>
    <visual>
      <origin rpy="1.5708 0 0" xyz="0 0 0"/>
      <geometry>
        <mesh filename="../../../../gazebo_scorpio_plugin/models/robots/meshes/parallel__scorpio_elev1__l3_hull.dae"/>
      </geometry>
      <material name="">
        <color rgba="0.752941176470588 0.752941176470588 0.752941176470588 1"/>
      </material>
    </visual>
  </link>

 <joint name="joint3" type="continuous">
    <origin xyz="0.22 0 0" rpy="0 0 0" />
    <parent link="link2" />
    <child link="link3" />
    <axis xyz="0 0 1" />
  </joint>

  <link name="link3">
     <inertial>
      <mass value="0.96506968"/>
      <origin rpy="0 0 0" xyz="0.05539938 -0.04550861 0.03305080"/>
      <inertia ixx="0.00194689" ixy="-0.00041897" ixz="-0.00001187" iyy="0.00108580" iyz="-0.00000204" izz="0.00181433"/>
    </inertial>
    <visual>
      <origin rpy="1.5708 0 0" xyz="0 0.075025 0"/>
      <geometry>
        <mesh filename="../../../../gazebo_scorpio_plugin/models/robots/meshes/parallel__scorpio_elev1__l2_hull.dae"/>
      </geometry>
      <material name="">
        <color rgba="0.752941176470588 0.752941176470588 0.752941176470588 1"/>
      </material>
    </visual>
  </link>
 
  <joint name="joint4" type="continuous">
    <origin xyz="0 0.075025 0" rpy="0 0 0" />
    <parent link="link3" />
    <child link="link4" />
    <axis xyz="0 0 1" />
  </joint>

  <link name="link4">
     <inertial>
      <mass value="1.09010204"/>
      <origin rpy="0 0 0" xyz="0.11968406 0.00015676 0.00077126"/>
      <inertia ixx="0.00163433" ixy="-0.00000800" ixz="-0.00013278" iyy="0.00610466" iyz="-0.00000123" izz="0.00721423"/>
    </inertial>
    <visual>
      <origin rpy="1.5708 0 0" xyz="-0.22 0 0"/>
      <geometry>
        <mesh filename="../../../../gazebo_scorpio_plugin/models/robots/meshes/parallel__scorpio_elev1__l1_hull.dae"/>
      </geometry>
      <material name="">
        <color rgba="0.752941176470588 0.752941176470588 0.752941176470588 1"/>
      </material>
    </visual>
  </link>


  <joint name="joint5" type="continuous">
    <origin xyz="0.065 0.035 -0.065" rpy="1.5708 0 0" />
    <parent link="link3" />
    <child link="link5" />
    <axis xyz="0 0 1" />
  </joint>


  <link name="link5">
    <inertial>
      <mass value="0.93229200"/>
      <origin rpy="0 0 0" xyz="0.04880378 0.06574464 -0.00765844"/>
      <inertia ixx="0.00175861" ixy="0.00003237" ixz="-0.00022338" iyy="0.00151576" iyz="-0.00000289" izz="0.00153999"/>
    </inertial>
    <visual>
      <origin rpy="0 0 0" xyz="0 0 0"/>
      <geometry>
        <mesh filename="../../../../gazebo_scorpio_plugin/models/robots/meshes/scorpio_yaw2_hull.dae"/>
      </geometry>
      <material name="">
        <color rgba="0.752941176470588 0.752941176470588 0.752941176470588 1"/>
      </material>
    </visual>
  </link>
 
  <joint name="joint6" type="continuous">
    <origin xyz="0.09 0.065 0.040025" rpy="-1.5708 0 0" />
    <parent link="link5" />
    <child link="link6" />
    <axis xyz="0 0 1" />
  </joint>

  <link name="link6">
  <inertial>
      <mass value="0.86101268"/>
      <origin rpy="0 0 0" xyz="0.12122970 -0.00077030 0.00730440"/>
      <inertia ixx="0.00102826" ixy="0.00002087" ixz="-0.00011564" iyy="0.00504132" iyz="-0.00000639" izz="0.00576250"/>
    </inertial>
    <visual>
      <origin rpy="1.5708 0 0" xyz="0 0 0"/>
      <geometry>
        <mesh filename="../../../../gazebo_scorpio_plugin/models/robots/meshes/parallel__scorpio_elev2__l3_hull.dae"/>
      </geometry>
      <material name="">
        <color rgba="0.752941176470588 0.752941176470588 0.752941176470588 1"/>
      </material>
    </visual>
  </link>

 <joint name="joint7" type="continuous">
    <origin xyz="0.22 0 0" rpy="0 0 0" />
    <parent link="link6" />
    <child link="link7" />
    <axis xyz="0 0 1" />
  </joint>

  <link name="link7">
    <inertial>
      <mass value="0.79358667"/>
      <origin rpy="0 0 0" xyz="0.06851225 0.00134854 0.02888846"/>
      <inertia ixx="0.00084161" ixy="-0.00004494" ixz="-0.00003202" iyy="0.00100312" iyz="0.00000025" izz="0.00102847"/>
    </inertial>
    <visual>
      <origin rpy="1.5708 0 0" xyz="0 0.075025 0"/>
      <geometry>
        <mesh filename="../../../../gazebo_scorpio_plugin/models/robots/meshes/parallel__scorpio_elev2__l2_hull.dae"/>
      </geometry>
      <material name="">
        <color rgba="0.752941176470588 0.752941176470588 0.752941176470588 1"/>
      </material>
    </visual>
  </link>

  <joint name="joint8" type="continuous">
    <origin xyz="0 0.075025 0" rpy="0 0 0" />
    <parent link="link7" />
    <child link="link8" />
    <axis xyz="0 0 1" />
  </joint>
 
  <link name="link8"> 
    <inertial>
      <mass value="1.09010204"/>
      <origin rpy="0 0 0" xyz="0.11968406 0.00015676 0.00077126"/>
      <inertia ixx="0.00163433" ixy="-0.00000800" ixz="-0.00013278" iyy="0.00610466" iyz="-0.00000123" izz="0.00721423"/>
    </inertial>
    <visual>
      <origin rpy="1.5708 0 0" xyz="-0.22 0 0"/>
      <geometry>
        <mesh filename="../../../../gazebo_scorpio_plugin/models/robots/meshes/parallel__scorpio_elev2__l1_hull.dae"/>
      </geometry>
      <material name="">
        <color rgba="0.752941176470588 0.752941176470588 0.752941176470588 1"/>
      </material>
    </visual>
  </link>

  <link name="link7_end">
    <inertial>
      <origin xyz="0 0 0" rpy="0 0 0" />
      <!--<mass value="0.00000001" />-->
      <!--<inertia ixx="1.e-9" ixy="0.0" ixz="0.0" iyy="1.e-9" iyz="0.0" izz="1.e-9" />-->
      <mass value="0.00001" />
      <inertia ixx="0.00001" ixy="0.0" ixz="0.0" iyy="0.00001" iyz="0.0" izz="0.00001" />
    </inertial>
  </link>

  <joint name="link7_end" type="fixed">
    <origin xyz="0 0.075025 0" rpy="1.5708 0 0" />
    <parent link="link7" />
    <child link="link7_end" />
  </joint>

  <joint name="joint9" type="continuous">
    <origin rpy="0 -0.7854 0" xyz="0.10096 0 0.048529"/>
    <parent link="link7_end" />
    <child link="link9" />
    <axis xyz="0 0 1" />
  </joint>

  <link name="link9">
   <inertial>
      <mass value="0.61742656"/>
      <origin rpy="0 0 0" xyz="0.02618812 -0.06026687 -0.05029391"/>
      <inertia ixx="0.00049346" ixy="-0.00005954" ixz="-0.00015627" iyy="0.00067920" iyz="0.00009425" izz="0.00043236"/>
    </inertial>
    <visual>
      <origin rpy="0 0 0" xyz="0 0 0"/>
      <geometry>
        <mesh filename="../../../../gazebo_scorpio_plugin/models/robots/meshes/scorpio_wrist_skewed_hull.dae"/>
      </geometry>
      <material name="">
        <color rgba="0.752941176470588 0.752941176470588 0.752941176470588 1"/>
      </material>
    </visual>
  </link>

  <joint name="joint10" type="continuous">
     <!--<joint name="wrist_pitch" type="fixed"> -->
    <origin rpy="0 0.7854 0" xyz="0.034604 -0.04372 -0.060104"/>
    <parent link="link9"/>
    <child link="scorpio_wrist_pitch"/>
    <axis xyz="0 1 0"/>
<!--    <limit effort="200" lower="-2.2000000" upper="1.0000000" velocity="0"/> -->
  </joint>

  <link name="scorpio_wrist_pitch">
    <inertial>
      <mass value="0.56501641"/>
      <origin rpy="0 0 0" xyz="-0.00022504 0.05030401 0.00234299"/>
      <inertia ixx="0.00042006" ixy="-0.00000558" ixz="0.00000093" iyy="0.00021226" iyz="-0.00001417" izz="0.00052578"/>
    </inertial>
    <visual>
      <origin rpy="0 0 0" xyz="0 0 0"/>
      <geometry>
        <mesh filename="../../../../gazebo_scorpio_plugin/models/robots/meshes/scorpio_wrist_pitch_hull.dae"/>
      </geometry>
      <material name="">
        <color rgba="0.752941176470588 0.752941176470588 0.752941176470588 1"/>
      </material>
    </visual>
  </link>
  <!--===========================WRIST ROLL PRE FT===========================-->
  <joint name="joint11" type="continuous">
<!--  <joint name="joint11" type="revolute"> -->
     <!--<joint name="wrist_roll" type="fixed"> -->
    <origin rpy="0 0 1.5708" xyz="0 0.04372 -0.01728"/>
    <parent link="scorpio_wrist_pitch"/>
    <child link="gripper_attachment_point"/>
    <axis xyz="0 0 1"/>
<!--    <limit effort="200" lower="-3.1416" upper="3.1416" velocity="0"/> -->
  </joint>
  <link name="gripper_attachment_point">
    <inertial>
      <origin rpy="0 0 0" xyz="0.000 0.000 0.000"/>
      <mass value="0.001"/>
      <inertia ixx="0.0001" ixy="0" ixz="0" iyy="0.0001" iyz="0" izz="0.0001"/>
    </inertial>
  </link>
  <!--===========================FT SENSOR TODO: MASS===========================-->

  <joint name="wrist_ft" type="fixed">
    <origin rpy="0 0 0" xyz="0.000 0.000 -0.028"/>
    <parent link="gripper_attachment_point"/>
    <child link="wrist_ft"/>
   </joint>

  <link name="wrist_ft">
    <inertial>
      <origin rpy="0 0 0" xyz="0.000 0.000 0.000"/>
      <mass value="0.050"/>
      <inertia ixx="0.0001" ixy="0" ixz="0" iyy="0.0001" iyz="0" izz="0.0001"/>
    </inertial>
    <visual>
      <origin rpy="0 0 0" xyz="0 0 0.014"/>
      <geometry>
        <cylinder length="0.028" radius="0.020"/>
      </geometry>
      <material name="">
        <color rgba="0.752941176470588 0.752941176470588 0.752941176470588 1"/>
      </material>
    </visual>
  </link>

  <!--===========================END EFFECTOR===========================-->
<!--
  <joint name="end_effector" type="fixed">
    <origin rpy="0 1.570796326 0" xyz="0.000 0.000 -0.0805"/>
    <parent link="robotiq_85_base_link"/>
    <child link="end_effector"/>
  </joint>
  <link name="end_effector">
    <inertial>
      <origin rpy="0 0 0" xyz="0.000 0.000 0.000"/>
      <mass value="0.001"/>
      <inertia ixx="0.0001" ixy="0" ixz="0" iyy="0.0001" iyz="0" izz="0.0001"/>
    </inertial>
  </link>

  <link name="link4_end">
    <inertial>
      <origin xyz="0 0 0" rpy="0 0 0" />
      <mass value="0.00001" />
      <inertia ixx="0.00001" ixy="0.00001" ixz="0.00001" iyy="0.00001" iyz="0.00001" izz="0.00001" />
    </inertial>
  </link>
  <joint name="link4_end" type="fixed">
    <origin xyz="-0.22 0 0" rpy="0 0 0" />
    <parent link="link4" />
    <child link="link4_end" />
</joint>

  <link name="link8_end">
    <inertial>
      <origin xyz="0 0 0" rpy="0 0 0" />
      <mass value="0.00001" />
      <inertia ixx="0.00001" ixy="0.00001" ixz="0.00001" iyy="0.00001" iyz="0.00001" izz="0.00001" />
    </inertial>
  </link>
  <joint name="link8_end" type="fixed">
    <origin xyz="-0.22 0 0" rpy="0 0 0" />
    <parent link="link8" />
    <child link="link8_end" />
  </joint>
-->

<!-- ################################################################# -->
<!-- Not sure if this is used or necessary for PnC/Scorpio -->
<!--     <link name="tool_frame"/>
    <joint name="tool_frame_joint" type="fixed">
        <origin xyz="0 0 0.120" rpy="0 0 0" />
        <parent link="gripper_attachment_point" />
        <parent link="wrist_ft" />
        <child link="tool_frame" />
        <axis xyz="0 0 0" />
    </joint> -->
  <link name="end_effector">
      <inertial>
      <origin rpy="0 0 0" xyz="0.000 0.000 0.000"/>
      <mass value="0.001"/>
      <inertia ixx="0.0001" ixy="0" ixz="0" iyy="0.0001" iyz="0" izz="0.0001"/>
    </inertial>
  </link>
  <joint name="end_effector" type="fixed">
      <!-- <origin xyz="0 0 -0.0615250000000001" rpy="0 0 0" /> -->
      <!-- <origin xyz="0 0 -0.0615250000000001" rpy="3.14159265358979 1.09937075168372E-32 0" /> -->
      <origin xyz="0 0 0.120" rpy="0 0 0" />
      <!-- <origin xyz="0 0 -0.0805" rpy="0 1.570796326 0" /> -->
      <parent link="robotiq_85_base_link" />
      <child link="end_effector" />
      <axis xyz="0 0 0" />
  </joint>    
<!-- ########################################################################### -->
    <!-- This joint was added by Kinova -->
  <!-- <joint name="gripper_base_joint" type="fixed"> -->
  <joint name="griper_base" type="fixed">
      <!-- <parent link="gripper_attachment_point"/> -->
      <parent link="wrist_ft"/>
      <child link="robotiq_85_base_link"/>
      <origin rpy="3.1415 0 1.57" xyz="0.000 0.000 0.000"/>
      <!-- <origin rpy="3.1415 0 0" xyz="0.000 0.000 0.000"/> -->
      <!-- <origin rpy="0.0 0.0 1.57" xyz="0.0 0.0 0.0"/> -->
  </joint>

  <link name="robotiq_85_base_link">
  <!-- <link name="robotiq_arg2f_base_link"> -->
    <inertial>
      <origin xyz="8.625E-08 -4.6583E-06 0.03145" rpy="0 0 0" />
      <mass value="0.22652" />
      <inertia ixx="0.00020005" ixy="-4.2442E-10" ixz="-2.9069E-10" iyy="0.00017832" iyz="-3.4402E-08" izz="0.00013478" />
    </inertial>
    <visual>
      <origin xyz="0 0 0" rpy="0 0 0" />
      <geometry>
        <mesh filename="../../../../gazebo_scorpio_plugin/models/robotiq_2f_85/meshes/collision/robotiq_arg2f_base_link.stl" />
      </geometry>
      <material name="">
        <color rgba="0.1 0.1 0.1 1" />
      </material>
    </visual>
    <collision>
      <origin xyz="0 0 0" rpy="0 0 0" />
      <geometry>
         <mesh filename="../../../../gazebo_scorpio_plugin/models/robotiq_2f_85/meshes/collision/robotiq_arg2f_base_link.stl" />
      </geometry>
    </collision>
  </link>

<!-- ################################################################# -->
<!-- ################# LEFT LINKS #################### -->

  <link name="left_outer_knuckle">
    <inertial>
      <origin xyz="-0.000200000000003065 0.0199435877845359 0.0292245259211331" rpy="0 0 0" />
      <mass value="0.00853198276973456" />
      <inertia ixx="2.89328108496468E-06" ixy="-1.57935047237397E-19" ixz="-1.93980378593255E-19" iyy="1.86719750325683E-06" iyz="-1.21858577871576E-06" izz="1.21905238907251E-06" />
    </inertial>
    <visual>
      <origin xyz="0 0 0" rpy="0 0 0" />
      <geometry>
        <mesh filename="../../../../gazebo_scorpio_plugin/models/robotiq_2f_85/meshes/visual/robotiq_arg2f_85_outer_knuckle.dae" scale="0.001 0.001 0.001"/>
      </geometry>
      <material name="">
        <color rgba="0.792156862745098 0.819607843137255 0.933333333333333 1" />
      </material>
    </visual>
    <collision>
      <origin xyz="0 0 0" rpy="0 0 0" />
      <geometry>
        <mesh filename="../../../../gazebo_scorpio_plugin/models/robotiq_2f_85/meshes/collision/robotiq_arg2f_85_outer_knuckle.dae" scale="0.001 0.001 0.001"/>
      </geometry>
    </collision>
  </link>

  <link name="left_outer_finger">
    <inertial>
      <origin xyz="0.00030115855001899 0.0373907951953854 -0.0208027427000385" rpy="0 0 0" />
      <mass value="0.022614240507152" />
      <inertia ixx="1.52518312458174E-05" ixy="9.76583423954399E-10" ixz="-5.43838577022588E-10" iyy="6.17694243867776E-06" iyz="6.78636130740228E-06" izz="1.16494917907219E-05" />
    </inertial>
    <visual>
      <origin xyz="0 0 0" rpy="0 0 0" />
      <geometry>
        <mesh filename="../../../../gazebo_scorpio_plugin/models/robotiq_2f_85/meshes/visual/robotiq_arg2f_85_outer_finger.dae" scale="0.001 0.001 0.001"/>
      </geometry>
      <material name="">
        <color rgba="0.1 0.1 0.1 1" />
      </material>
    </visual>
    <collision>
      <origin xyz="0 0 0" rpy="0 0 0" />
      <geometry>
        <mesh filename="../../../../gazebo_scorpio_plugin/models/robotiq_2f_85/meshes/collision/robotiq_arg2f_85_outer_finger.dae" scale="0.001 0.001 0.001"/>
      </geometry>
    </collision>
  </link>

  <link name="left_inner_knuckle">
    <inertial>
      <origin xyz="0.000123011831763771 0.0507850843201817 0.00103968640075166" rpy="0 0 0" />
     <mass value="0.0271177346495152" />
      <inertia ixx="2.61910379223783E-05" ixy="-2.43616858946494E-07" ixz="-6.37789906117123E-09" iyy="2.8270243746167E-06" iyz="-5.37200748039765E-07" izz="2.83695868220296E-05" />
    </inertial>
    <visual>
      <origin xyz="0 0 0" rpy="0 0 0" />
      <geometry>
        <mesh filename="../../../../gazebo_scorpio_plugin/models/robotiq_2f_85/meshes/visual/robotiq_arg2f_85_inner_knuckle.dae" scale="0.001 0.001 0.001"/>
      </geometry>
      <material name="">
        <color rgba="0.1 0.1 0.1 1" />
      </material>
    </visual>
    <collision>
      <origin xyz="0 0 0" rpy="0 0 0" />
      <geometry>
        <mesh filename="../../../../gazebo_scorpio_plugin/models/robotiq_2f_85/meshes/collision/robotiq_arg2f_85_inner_knuckle.dae" scale="0.001 0.001 0.001"/>
      </geometry>
    </collision>
  </link>

  <link name="left_inner_finger">
    <inertial>
      <origin xyz="0.000299999999999317 0.0160078233491243 -0.0136945669206257" rpy="0 0 0" />
      <mass value="0.0104003125914103" />
      <inertia ixx="2.71909453810972E-06" ixy="1.35402465472579E-21" ixz="-7.1817349065269E-22" iyy="7.69100314106116E-07" iyz="6.74715432769696E-07" izz="2.30315190420171E-06" />
    </inertial> 
    <visual>
      <origin xyz="0 0 0" rpy="0 0 0" />
      <geometry>
        <mesh filename="../../../../gazebo_scorpio_plugin/models/robotiq_2f_85/meshes/visual/robotiq_arg2f_85_inner_finger.dae" scale="0.001 0.001 0.001"/>
      </geometry>
      <material name="">
        <color rgba="0.1 0.1 0.1 1" />
      </material>
    </visual>
    <collision>
      <origin xyz="0 0 0" rpy="0 0 0" />
      <geometry>
        <mesh filename="../../../../gazebo_scorpio_plugin/models/robotiq_2f_85/meshes/collision/robotiq_arg2f_85_inner_finger.dae" scale="0.001 0.001 0.001" />
      </geometry>
    </collision>
  </link>

<!--   <link name="left_inner_finger_pad">
    <visual>
      <origin xyz="0 0 0" rpy="0 0 0" />
      <geometry>
        <box size="0.022 0.00635 0.0375"/>
      </geometry>
      <material name="">
        <color rgba="0.9 0.9 0.9 1" />
      </material>
    </visual>
    <collision>
      <origin xyz="0 0 0" rpy="0 0 0" />
      <geometry>
         <box size="0.022 0.00635 0.0375"/>
      </geometry>
      <material name="">
        <color rgba="0.9 0.0 0.0 1" />
      </material>
    </collision>
  </link> -->

<!-- ################# RIGHT LINKS #################### -->
 <link name="right_outer_knuckle">
    <inertial>
      <origin xyz="-0.000200000000003065 0.0199435877845359 0.0292245259211331" rpy="0 0 0" />
      <mass value="0.00853198276973456" />
      <inertia ixx="2.89328108496468E-06" ixy="-1.57935047237397E-19" ixz="-1.93980378593255E-19" iyy="1.86719750325683E-06" iyz="-1.21858577871576E-06" izz="1.21905238907251E-06" />
    </inertial>
    <visual>
      <origin xyz="0 0 0" rpy="0 0 0" />
      <geometry>
        <mesh filename="../../../../gazebo_scorpio_plugin/models/robotiq_2f_85/meshes/visual/robotiq_arg2f_85_outer_knuckle.dae" scale="0.001 0.001 0.001"/>
      </geometry>
      <material name="">
        <color rgba="0.792156862745098 0.819607843137255 0.933333333333333 1" />
      </material>
    </visual>
    <collision>
      <origin xyz="0 0 0" rpy="0 0 0" />
      <geometry>
        <mesh filename="../../../../gazebo_scorpio_plugin/models/robotiq_2f_85/meshes/collision/robotiq_arg2f_85_outer_knuckle.dae" scale="0.001 0.001 0.001"/>
      </geometry>
    </collision>
  </link>
  
  <link name="right_outer_finger">
    <inertial>
      <origin xyz="0.00030115855001899 0.0373907951953854 -0.0208027427000385" rpy="0 0 0" />
      <mass value="0.022614240507152" />
      <inertia ixx="1.52518312458174E-05" ixy="9.76583423954399E-10" ixz="-5.43838577022588E-10" iyy="6.17694243867776E-06" iyz="6.78636130740228E-06" izz="1.16494917907219E-05" />
    </inertial>
    <visual>
      <origin xyz="0 0 0" rpy="0 0 0" />
      <geometry>
        <mesh filename="../../../../gazebo_scorpio_plugin/models/robotiq_2f_85/meshes/visual/robotiq_arg2f_85_outer_finger.dae" scale="0.001 0.001 0.001"/>
      </geometry>
      <material name="">
        <color rgba="0.1 0.1 0.1 1" />
      </material>
    </visual>
    <collision>
      <origin xyz="0 0 0" rpy="0 0 0" />
      <geometry>
        <mesh filename="../../../../gazebo_scorpio_plugin/models/robotiq_2f_85/meshes/collision/robotiq_arg2f_85_outer_finger.dae" scale="0.001 0.001 0.001"/>
      </geometry>
    </collision>
  </link>

  <link name="right_inner_knuckle">
    <inertial>
      <origin xyz="0.000123011831763771 0.0507850843201817 0.00103968640075166" rpy="0 0 0" />
     <mass value="0.0271177346495152" />
      <inertia ixx="2.61910379223783E-05" ixy="-2.43616858946494E-07" ixz="-6.37789906117123E-09" iyy="2.8270243746167E-06" iyz="-5.37200748039765E-07" izz="2.83695868220296E-05" />
    </inertial>
    <visual>
      <origin xyz="0 0 0" rpy="0 0 0" />
      <geometry>
        <mesh filename="../../../../gazebo_scorpio_plugin/models/robotiq_2f_85/meshes/visual/robotiq_arg2f_85_inner_knuckle.dae" scale="0.001 0.001 0.001"/>
      </geometry>
      <material name="">
        <color rgba="0.1 0.1 0.1 1" />
      </material>
    </visual>
    <collision>
      <origin xyz="0 0 0" rpy="0 0 0" />
      <geometry>
        <mesh filename="../../../../gazebo_scorpio_plugin/models/robotiq_2f_85/meshes/collision/robotiq_arg2f_85_inner_knuckle.dae" scale="0.001 0.001 0.001"/>
      </geometry>
    </collision>
  </link>

  <link name="right_inner_finger">
    <inertial>
      <origin xyz="0.000299999999999317 0.0160078233491243 -0.0136945669206257" rpy="0 0 0" />
      <mass value="0.0104003125914103" />
      <inertia ixx="2.71909453810972E-06" ixy="1.35402465472579E-21" ixz="-7.1817349065269E-22" iyy="7.69100314106116E-07" iyz="6.74715432769696E-07" izz="2.30315190420171E-06" />
    </inertial> 
    <visual>
      <origin xyz="0 0 0" rpy="0 0 0" />
      <geometry>
        <mesh filename="../../../../gazebo_scorpio_plugin/models/robotiq_2f_85/meshes/visual/robotiq_arg2f_85_inner_finger.dae" scale="0.001 0.001 0.001"/>
      </geometry>
      <material name="">
        <color rgba="0.1 0.1 0.1 1" />
      </material>
    </visual>
    <collision>
      <origin xyz="0 0 0" rpy="0 0 0" />
      <geometry>
        <mesh filename="../../../../gazebo_scorpio_plugin/models/robotiq_2f_85/meshes/collision/robotiq_arg2f_85_inner_finger.dae" scale="0.001 0.001 0.001" />
      </geometry>
    </collision>
  </link>
<!-- 
  <link name="right_inner_finger_pad">
    <visual>
      <origin xyz="0 0 0" rpy="0 0 0" />
      <geometry>
        <box size="0.022 0.00635 0.0375"/>
      </geometry>
      <material name="">
        <color rgba="0.9 0.9 0.9 1" />
      </material>
    </visual>
    <collision>
      <origin xyz="0 0 0" rpy="0 0 0" />
      <geometry>
         <box size="0.022 0.00635 0.0375"/>
      </geometry>
      <material name="">
        <color rgba="0.9 0.0 0.0 1" />
      </material>
    </collision>
  </link>
 -->
<!-- ################# LEFT JOINTS #################### -->

  <joint name="finger_joint" type="fixed">
    <origin xyz="0 -0.0306011 0.054904" rpy="0 0 3.141592"/>
    <parent link="robotiq_85_base_link" />
    <child link="left_outer_knuckle" />
    <axis xyz="1 0 0" />
    <limit lower="0" upper="0.8" velocity="2.0" effort="1000" />
  </joint>

  <joint name="left_outer_finger_joint" type="fixed">
    <origin xyz="0 0.0315 -0.0041" rpy="0 0 0"/>
    <parent link="left_outer_knuckle" />
    <child link="left_outer_finger" />
    <axis xyz="1 0 0" />
  </joint>

  <joint name="left_inner_finger_joint" type="fixed">
    <origin xyz="0 0.0061 0.0471" rpy="0 0 0"/>
    <parent link="left_outer_finger" />
    <child link="left_inner_finger" />
    <axis xyz="1 0 0" />
    <limit lower="-0.8757" upper="0.8757" velocity="2.0" effort="1000" />
    <mimic joint="finger_joint" multiplier="-1" offset="0" />
  </joint>

<!--   <joint name="left_inner_finger_pad_joint" type="fixed">
    <origin xyz="0 -0.0220203446692936 0.03242" rpy="0 0 0"/>
    <parent link="left_inner_finger" />
    <child link="left_inner_finger_pad" />
    <axis xyz="0 0 1" />
  </joint> -->

  <joint name="left_inner_knuckle_joint" type="fixed">
    <!-- <origin xyz="0 ${reflect * -0.0127} 0.06142" rpy="${pi / 2 + .725} 0 ${(reflect - 1) * pi / 2}" /> -->
    <origin xyz="0 0.0127 0.06142" rpy="0 0 0"/>
    <parent link="robotiq_85_base_link" />
    <child link="left_inner_knuckle" />
    <axis xyz="1 0 0" />
    <limit lower="0" upper="0.8757" velocity="2.0" effort="1000" />
    <mimic joint="finger_joint" multiplier="1" offset="0" />
  </joint>

<!-- ################# RIGHT JOINTS #################### -->

  <joint name="right_outer_knuckle_joint" type="fixed">
    <origin xyz="0 0.0306011 0.054904" rpy="0 0 0"/>
    <parent link="robotiq_85_base_link" />
    <child link="right_outer_knuckle" />
    <axis xyz="1 0 0" />
    <limit lower="0" upper="0.81" velocity="2.0" effort="1000" />
    <mimic joint="finger_joint" multiplier="1" offset="0" />
  </joint>

  <joint name="right_outer_finger_joint" type="fixed">
    <origin xyz="0 0.0315 -0.0041" rpy="0 0 0"/>
    <parent link="right_outer_knuckle" />
    <child link="right_outer_finger" />
    <axis xyz="1 0 0" />
  </joint>

  <joint name="right_inner_finger_joint" type="fixed">
    <origin xyz="0 0.0061 0.0471" rpy="0 0 0"/>
    <parent link="right_outer_finger" />
    <child link="right_inner_finger" />
    <axis xyz="1 0 0" />
    <limit lower="-0.8757" upper="0.8757" velocity="2.0" effort="1000" />
    <mimic joint="finger_joint" multiplier="-1" offset="0" />
  </joint>
<!--   
  <joint name="right_inner_finger_pad_joint" type="fixed">
    <origin xyz="0 -0.0220203446692936 0.03242" rpy="0 0 0"/>
    <parent link="right_inner_finger" />
    <child link="right_inner_finger_pad" />
    <axis xyz="0 0 1" />
  </joint>
 -->
  <joint name="right_inner_knuckle_joint" type="fixed">
    <!-- <origin xyz="0 ${reflect * -0.0127} 0.06142" rpy="${pi / 2 + .725} 0 ${(reflect - 1) * pi / 2}" /> -->
    <origin xyz="0 -0.0127 0.06142" rpy="0 0 3.141592"/>
    <parent link="robotiq_85_base_link" />
    <child link="right_inner_knuckle" />
    <axis xyz="1 0 0" />
    <limit lower="0" upper="0.8757" velocity="2.0" effort="1000" />
    <mimic joint="finger_joint" multiplier="1" offset="0" />
  </joint>
<!--   <xacro:macro name="finger_joints" params="prefix fingerprefix reflect">
    <xacro:outer_finger_joint prefix="${prefix}" fingerprefix="${fingerprefix}"/>
    <xacro:inner_knuckle_joint prefix="${prefix}" fingerprefix="${fingerprefix}" reflect="${reflect}"/>
    <xacro:inner_finger_joint prefix="${prefix}" fingerprefix="${fingerprefix}"/>
    <xacro:inner_finger_pad_joint prefix="${prefix}" fingerprefix="${fingerprefix}"/>
  </xacro:macro>

  <xacro:macro name="finger_links" params="prefix fingerprefix stroke">
    <xacro:outer_knuckle prefix="${prefix}" fingerprefix="${fingerprefix}" stroke="${stroke}"/>
    <xacro:outer_finger prefix="${prefix}" fingerprefix="${fingerprefix}" stroke="${stroke}"/>
    <xacro:inner_finger prefix="${prefix}" fingerprefix="${fingerprefix}" stroke="${stroke}"/>
    <xacro:inner_finger_pad prefix="${prefix}" fingerprefix="${fingerprefix}"/>
    <xacro:inner_knuckle prefix="${prefix}" fingerprefix="${fingerprefix}" stroke="${stroke}"/>
  </xacro:macro> -->

<!-- ################################################ -->
<!--   <joint name="end_effector" type="fixed">
    <origin rpy="0 1.570796326 0" xyz="0.000 0.000 -0.0805"/>
    <parent link="robotiq_arg2f_base_link"/>
    <child link="end_effector"/>
  </joint>
  <link name="end_effector">
    <inertial>
      <origin rpy="0 0 0" xyz="0.000 0.000 0.000"/>
      <mass value="0.001"/>
      <inertia ixx="0.0001" ixy="0" ixz="0" iyy="0.0001" iyz="0" izz="0.0001"/>
    </inertial>
  </link> -->

  <link name="link4_end">
    <inertial>
      <origin xyz="0 0 0" rpy="0 0 0" />
      <mass value="0.00001" />
      <inertia ixx="0.00001" ixy="0.00001" ixz="0.00001" iyy="0.00001" iyz="0.00001" izz="0.00001" />
    </inertial>
  </link>
  <joint name="link4_end" type="fixed">
    <origin xyz="-0.22 0 0" rpy="0 0 0" />
    <parent link="link4" />
    <child link="link4_end" />
</joint>

  <link name="link8_end">
    <inertial>
      <origin xyz="0 0 0" rpy="0 0 0" />
      <mass value="0.00001" />
      <inertia ixx="0.00001" ixy="0.00001" ixz="0.00001" iyy="0.00001" iyz="0.00001" izz="0.00001" />
    </inertial>
  </link>
  <joint name="link8_end" type="fixed">
    <origin xyz="-0.22 0 0" rpy="0 0 0" />
    <parent link="link8" />
    <child link="link8_end" />
  </joint>
</robot>
